'Report not ready! data_validate.stderr: Traceback (most recent call last):\r\n  File "D:\\Projects\\AdaptaBrasil\\data_validate\\main.py", line 22, in <module>\r\n    orc.run(input_folder=args.input_folder,output_folder=args.output_folder, no_spellchecker=args.no_spellchecker, lang_dict=args.lang_dict, no_warning_titles_length=args.no_warning_titles_length, no_time=args.no_time, debug=args.debug, no_version=args.no_version)\r\n  File "D:\\Projects\\AdaptaBrasil\\data_validate\\src\\orchestrator.py", line 420, in run\r\n    results_tests.append(["Indicadores em valores e proporcionalidades", *flatten(*sp_proportionalities.verify_ids_values_proportionalities(df_sp_proportionalities, df_sp_values, SP_PROPORTIONALITIES_COLUMNS.NAME_SP, SP_VALUES_COLUMNS.NAME_SP))])\r\n  File "D:\\Projects\\AdaptaBrasil\\data_validate\\src\\myparser\\sp_proportionalities.py", line 440, in verify_ids_values_proportionalities\r\n    proportionalities_indicators_lvl1.remove(\'Unnamed: 0_level_0\')\r\nValueError: list.remove(x): x not in list\r\n, data_validate.stdout: \r\nD:\\Projects\\AdaptaBrasil\\canoa\\carranca>Rem Batch to run data_validate FROM `canoa` \r\nActivating data_validate environment...\r\nRunning data_validate...\r\n\r\n\r\n\r\nINICIANDO A VERIFICAÇÃO DOS ARQUIVOS DA PASTA: D:\\Projects\\AdaptaBrasil\\data_tunnel\\00212\\data\r\nDeactivating data_validate environment...\r\nReturning to Canoa.\r\n'